
# Node: 'model/add_1/add' required broadcastable shapes [[{{node model/add_1/add}}]] [Op:__inference_train_function_16302]

I am implementing deep model using TensorFlow Keras. I checked all the shapes of my model, it is fine. But when I start to train the model, I am getting the following error:
Node: 'model/add_1/add'
required broadcastable shapes
     [[{{node model/add_1/add}}]] [Op:__inference_train_function_16302]

Here is the Complete Trackback:
Traceback (most recent call last):
  File "/home/anafees/.local/lib/python3.9/site-packages/keras/utils/traceback_utils.py", line 67, in error_handler
    raise e.with_traceback(filtered_tb) from None
  File "/home/anafees/.local/lib/python3.9/site-packages/tensorflow/python/eager/execute.py", line 54, in quick_execute
    tensors = pywrap_tfe.TFE_Py_Execute(ctx._handle, device_name, op_name,
tensorflow.python.framework.errors_impl.InvalidArgumentError: Graph execution error:

Detected at node 'model/add_1/add' defined at (most recent call last):
    File "/home/anafees/.pycharm_helpers/pydev/pydevd.py", line 2173, in <module>
      main()
    File "/home/anafees/.pycharm_helpers/pydev/pydevd.py", line 2164, in main
      globals = debugger.run(setup['file'], None, None, is_module)
    File "/home/anafees/.pycharm_helpers/pydev/pydevd.py", line 1476, in run
      return self._exec(is_module, entry_point_fn, module_name, file, globals, locals)
    File "/home/anafees/.pycharm_helpers/pydev/pydevd.py", line 1483, in _exec
      pydev_imports.execfile(file, globals, locals)  # execute the script
    File "/home/anafees/.pycharm_helpers/pydev/_pydev_imps/_pydev_execfile.py", line 18, in execfile
      exec(compile(contents+"\n", file, 'exec'), glob, loc)
    File "/home/anafees/HAR-Project2/main_hos_mixup.py", line 172, in <module>
      f_score = hospital(test_scores_storage)
    File "/home/anafees/HAR-Project2/main_hos_mixup.py", line 144, in hospital
      model = modeling(seg_train_x, seg_train_y, seg_val_x, seg_val_y,
    File "/home/anafees/HAR-Project2/Model_Training_Cutmix.py", line 228, in modeling
      history = model.fit(train_ds, epochs=total_epoch,
    File "/home/anafees/.local/lib/python3.9/site-packages/keras/utils/traceback_utils.py", line 64, in error_handler
      return fn(*args, **kwargs)
    File "/home/anafees/.local/lib/python3.9/site-packages/keras/engine/training.py", line 1384, in fit
      tmp_logs = self.train_function(iterator)
    File "/home/anafees/.local/lib/python3.9/site-packages/keras/engine/training.py", line 1021, in train_function
      return step_function(self, iterator)
    File "/home/anafees/.local/lib/python3.9/site-packages/keras/engine/training.py", line 1010, in step_function
      outputs = model.distribute_strategy.run(run_step, args=(data,))
    File "/home/anafees/.local/lib/python3.9/site-packages/keras/engine/training.py", line 1000, in run_step
      outputs = model.train_step(data)
    File "/home/anafees/.local/lib/python3.9/site-packages/keras/engine/training.py", line 859, in train_step
      y_pred = self(x, training=True)
    File "/home/anafees/.local/lib/python3.9/site-packages/keras/utils/traceback_utils.py", line 64, in error_handler
      return fn(*args, **kwargs)
    File "/home/anafees/.local/lib/python3.9/site-packages/keras/engine/base_layer.py", line 1096, in __call__
      outputs = call_fn(inputs, *args, **kwargs)
    File "/home/anafees/.local/lib/python3.9/site-packages/keras/utils/traceback_utils.py", line 92, in error_handler
      return fn(*args, **kwargs)
    File "/home/anafees/.local/lib/python3.9/site-packages/keras/engine/functional.py", line 451, in call
      return self._run_internal_graph(
    File "/home/anafees/.local/lib/python3.9/site-packages/keras/engine/functional.py", line 589, in _run_internal_graph
      outputs = node.layer(*args, **kwargs)
    File "/home/anafees/.local/lib/python3.9/site-packages/keras/utils/traceback_utils.py", line 64, in error_handler
      return fn(*args, **kwargs)
    File "/home/anafees/.local/lib/python3.9/site-packages/keras/engine/base_layer.py", line 1096, in __call__
      outputs = call_fn(inputs, *args, **kwargs)
    File "/home/anafees/.local/lib/python3.9/site-packages/keras/utils/traceback_utils.py", line 92, in error_handler
python-BaseException
      return fn(*args, **kwargs)
    File "/home/anafees/.local/lib/python3.9/site-packages/keras/layers/merge.py", line 183, in call
      return self._merge_function(inputs)
    File "/home/anafees/.local/lib/python3.9/site-packages/keras/layers/merge.py", line 259, in _merge_function
      output += inputs[i]
Node: 'model/add_1/add'
required broadcastable shapes
     [[{{node model/add_1/add}}]] [Op:__inference_train_function_16302]


        