
# botocore.exceptions.ClientError: An error occurred when calling the CreateModel operation: Requested image not found

I am trying to deploy a MLflow model with Amazon Sagemaker. I followed the usual procedure train the model, log the model in mlflow, I created the docker image that gets used by MLflow to serve the model and pushes it to Amazon SageMaker. After I tried to run the code below, but I keep to have errors as shown in the title.
This is the code:
image_url = '849711432510.dkr.ecr.us-east-1.amazonaws.com/mlflow-pyfunc'
# the model uri
model_uri = 'runs:/f5008b5a96144208ba2e3648d553fff5/models'
# your region
region = "us-east-1"
# the arn of the sagemaker deployment role
arn = "arn:aws:iam::849711432510:role/awssagemakerdeployment"

# deploy to the endpoint
mlflow.sagemaker.deploy(
    mode='create',
    app_name="IsolationForestTest",
    model_uri=model_uri,
    image_url=image_url,
    execution_role_arn=arn,
    #bucket='mlflow-sagemaker-us-east-1-849711432510',
    instance_type="ml.t2.medium",
    instance_count=1,
    region_name=region
)

The error is:
2022/11/01 15:17:09 INFO mlflow.sagemaker: Using the python_function flavor for deployment!
2022/11/01 15:17:10 INFO mlflow.sagemaker: No model data bucket specified, using the default bucket
2022/11/01 15:17:11 INFO mlflow.sagemaker: Default bucket `mlflow-sagemaker-us-east-1-849711432510` already exists. Skipping creation.
2022/11/01 15:17:13 INFO mlflow.sagemaker: tag response: {'ResponseMetadata': {'RequestId': 'EEZCNP8CJ9FT1SZJ', 'HostId': 'Lm+2Y8vSdKCAPlL40ipFbcyH5RS/G1s1gHd1w+Ls9eUNxjuqR1mrwxnnYpkMrIB6iUdTu2IKb/w=', 'HTTPStatusCode': 200, 'HTTPHeaders': {'x-amz-id-2': 'Lm+2Y8vSdKCAPlL40ipFbcyH5RS/G1s1gHd1w+Ls9eUNxjuqR1mrwxnnYpkMrIB6iUdTu2IKb/w=', 'x-amz-request-id': 'EEZCNP8CJ9FT1SZJ', 'date': 'Tue, 01 Nov 2022 14:17:15 GMT', 'server': 'AmazonS3', 'content-length': '0'}, 'RetryAttempts': 0}}
2022/11/01 15:17:13 INFO mlflow.sagemaker: Creating new endpoint with name: IsolationForestTest ...
Traceback (most recent call last):
  File "/root/anomaly_detection_ecg_part2/src/mlflow_deply_sagemaker.py", line 32, in <module>
    mlflow.sagemaker.deploy(
  File "/root/anomaly_detection_ecg_part2/venv/lib/python3.10/site-packages/mlflow/sagemaker/__init__.py", line 388, in deploy
    deployment_operation = _create_sagemaker_endpoint(
  File "/root/anomaly_detection_ecg_part2/venv/lib/python3.10/site-packages/mlflow/sagemaker/__init__.py", line 1438, in _create_sagemaker_endpoint
    model_response = _create_sagemaker_model(
  File "/root/anomaly_detection_ecg_part2/venv/lib/python3.10/site-packages/mlflow/sagemaker/__init__.py", line 1676, in _create_sagemaker_model
    model_response = sage_client.create_model(**create_model_args)
  File "/root/anomaly_detection_ecg_part2/venv/lib/python3.10/site-packages/botocore/client.py", line 507, in _api_call
    return self._make_api_call(operation_name, kwargs)
  File "/root/anomaly_detection_ecg_part2/venv/lib/python3.10/site-packages/botocore/client.py", line 943, in _make_api_call
    raise error_class(parsed_response, operation_name)
botocore.exceptions.ClientError: An error occurred (ValidationException) when calling the CreateModel operation: Requested image 849711432510.dkr.ecr.us-east-1.amazonaws.com/mlflow-pyfunc not found.

I am not sure if I have problems because there are some policies and permissions regarding IAM role that don't allow to deploy the model or something else. I am sure that the image exists both in Docker and AWS, so I am not sure where there is the problem.
I have tried to check permission of the policy "AmazonSageMakerFullAccess", but it seems right.

        