
# DataLoader worker (pid(s)) exited unexpectedly

When running my code I recieved this error message â€œ RuntimeError: DataLoader worker (pid(s) 8992) exited unexpectedly " after training start
I can't solve the problem
Start_args_module  :
model builder start :
load_data_start
start_metric_module
train_val_module_start : 
config :  <configparser.SafeConfigParser object at 0x7f766fdd8b90>
__ affichage des parametres de fichier config.ini __
                                               
NUM_Worker :  0
batch_size :  10
cuda :  True
multi_gpu :  False
image_size :  224
                                               
Model : resnet_split0 Experience : cross_validation
self.dataset :  None
videos_split :  [['SM686-7' 'train']
 ['LYI1079-2' 'train']
 ['GA817-1-8' 'train']
 ...
 ['TA239-2' 'test']
 ['GM537-7' 'test']
 ['AM33-2' 'test']]

Number of training videos : 564
train_dataset <load_data.SeqTrDataset object at 0x7f766fd70950>
kwargs {'sampler': <load_data.Sampler object at 0x7f766fde6b50>, 'collate_fn': <function collateSeq at 0x7f768dfc10e0>}
bsz 10
/usr/local/lib/python3.7/dist-packages/torch/utils/data/dataloader.py:566: UserWarning: This DataLoader will create 8 worker processes in total. Our suggested max number of worker in current system is 2, which is smaller than what this DataLoader is going to create. Please be aware that excessive worker creation might get DataLoader running slow or even freeze, lower the worker number to avoid potential slowness/freeze if necessary.
  cpuset_checked))
trainLoader <torch.utils.data.dataloader.DataLoader object at 0x7f766fde6a50>
videos_split :  [['SM686-7' 'train']
 ['LYI1079-2' 'train']
 ['GA817-1-8' 'train']
 ...
 ['TA239-2' 'test']
 ['GM537-7' 'test']
 ['AM33-2' 'test']]

____Epoch_begin____
Epoch 1  : train
metrDict initialise  : {'Loss': 0, 'Accuracy': 0, 'Accuracy (Viterbi)': 0}
RG434-_10 7 0
Traceback (most recent call last):
  File "/usr/local/lib/python3.7/dist-packages/torch/utils/data/dataloader.py", line 1163, in _try_get_data
    data = self._data_queue.get(timeout=timeout)
  File "/usr/lib/python3.7/multiprocessing/queues.py", line 105, in get
    raise Empty
_queue.Empty


 ** File "/usr/local/lib/python3.7/dist-packages/torch/utils/data/dataloader.py", line 1176, in _try_get_data
    raise RuntimeError('DataLoader worker (pid(s) {}) exited unexpectedly'.format(pids_str)) from e
RuntimeError: DataLoader worker (pid(s) 426) exited unexpectedly**

i set
NUM_Worker :  0
batch_size :  10
cuda :  True
multi_gpu :  False
image_size :  224

        