
# Tensorflow music generation with lstm - model.fit not working

My code for model.fit():
# Compile the model
lstm.compile(loss='sparse_categorical_crossentropy', optimizer='rmsprop')

lstm.summary()

# Train the model
lstm.fit(x=[trainChords, trainDurations], y=[targetChords, targetDurations], epochs=500, batch_size=64)

When I try to run it in Google Colab:
Model: "model_5"
__________________________________________________________________________________________________
 Layer (type)                   Output Shape         Param #     Connected to                     
==================================================================================================
 input_13 (InputLayer)          [(None, None)]       0           []                               
                                                                                                  
 input_14 (InputLayer)          [(None, None)]       0           []                               
                                                                                                  
 embedding_12 (Embedding)       (None, None, 64)     2048        ['input_13[0][0]']               
                                                                                                  
 embedding_13 (Embedding)       (None, None, 64)     2048        ['input_14[0][0]']               
                                                                                                  
 concatenate_6 (Concatenate)    (None, None, 64)     0           ['embedding_12[0][0]',           
                                                                  'embedding_13[0][0]']           
                                                                                                  
 lstm_6 (LSTM)                  (None, None, 512)    1181696     ['concatenate_6[0][0]']          
                                                                                                  
 dense_15 (Dense)               (None, None, 256)    131328      ['lstm_6[0][0]']                 
                                                                                                  
 dense_16 (Dense)               (None, None, 32)     8224        ['dense_15[0][0]']               
                                                                                                  
 dense_17 (Dense)               (None, None, 32)     8224        ['dense_15[0][0]']               
                                                                                                  
==================================================================================================
Total params: 1,333,568
Trainable params: 1,333,568
Non-trainable params: 0
__________________________________________________________________________________________________
Epoch 1/500
---------------------------------------------------------------------------
InvalidArgumentError                      Traceback (most recent call last)
<ipython-input-46-946a5b0f8b7f> in <module>
      5 
      6 # Train the model
----> 7 lstm.fit(x=[trainChords, trainDurations], y=[targetChords, targetDurations], epochs=500, batch_size=64)

1 frames
/usr/local/lib/python3.7/dist-packages/tensorflow/python/eager/execute.py in quick_execute(op_name, num_outputs, inputs, attrs, ctx, name)
     53     ctx.ensure_initialized()
     54     tensors = pywrap_tfe.TFE_Py_Execute(ctx._handle, device_name, op_name,
---> 55                                         inputs, attrs, num_outputs)
     56   except core._NotOkStatusException as e:
     57     if name is not None:

InvalidArgumentError: Graph execution error:

Detected at node 'model_5/embedding_12/embedding_lookup' defined at (most recent call last):
    File "/usr/lib/python3.7/runpy.py", line 193, in _run_module_as_main
      "__main__", mod_spec)
    File "/usr/lib/python3.7/runpy.py", line 85, in _run_code
      exec(code, run_globals)
    File "/usr/local/lib/python3.7/dist-packages/ipykernel_launcher.py", line 16, in <module>
      app.launch_new_instance()
    File "/usr/local/lib/python3.7/dist-packages/traitlets/config/application.py", line 846, in launch_instance
      app.start()
Node: 'model_5/embedding_12/embedding_lookup'
indices[56,0] = 4615 is not in [0, 32)
     [[{{node model_5/embedding_12/embedding_lookup}}]] [Op:__inference_train_function_48742]

Does anyone know what is going wrong? Perhaps it has something to do with the shapes?
I was hoping the model was able to train using the train and target data. Instead I get all these errors and I don't know even know what is going wrong.

        